Workbook

Sheet SB1
A1: Codigo | B1: Descripcion | C1: TS Estandar
A2: 000001 | B2: MERCADERIA SALDOS | C2: 503
A3: 000002 | B3: CINTA PELIGRO X 100 MTS DOBLE FAZ(CP100) | C3: 503
A4: 000003 | B4: CINTA PELIGRO X 200 MTS DOBLE FAZ(CP200) | C4: 503
A5: 000004 | B5: PISTOLA APLICADORA SKELETOR REFORZADA | C5: 503
A6: 000005 | B6: PORTA PINCEL MAGNETICO | C6: 503
A7: 000006 | B7: COBERTURA PLASTICA MULTIUSO 3X3MTS.(AC315) | C7: 503
A8: 000007 | B8: COBERTURA PLASTICA MULTIUSO 3X4MTS.(AC316) | C8: 503
A9: 000008 | B9: COBERTURA PLASTICA MULTIUSO 3X5MTS.(AC317) | C9: 503
A10: 000009 | B10: FONDO ANTIOXIDO COLORIN ROJO X 0,250 | C10: 503
A11: 000010 | B11: ESMALTE SINTETICO TERSUAVE 2EN1 MATE NEGRO X 0,500 | C11: 503
A12: 000011 | B12: ESMALTE SINTETICO TERSUAVE 2EN1 MATE NEGRO X 1 | C12: 503
... A7103: 999998 | B7103: GENERICO 10 LITROS ESTANDAR | C7103: 503
A7104: A00010 | B7104: BIEN DE USO - VEHICULOS
A7105: A00011 | B7105: BIENES DE USO - EQUIPOS COMPUTACION
A7106: A00012 | B7106: BIENES DE USO - MUEBLES Y UTILES
A7107: A00100 | B7107: INGRESOS BRUTOS
A7108: A00101 | B7108: DREI
A7109: A00102 | B7109: IMPUESTO A LAS GANANCIAS
A7110: A00103 | B7110: IMPUESTO BIENES PERSONALES
A7111: A00104 | B7111: ANTICIPO IMPUESTO A LAS GANANCIAS
A7112: A00105 | B7112: ANTICIPO BIENES PERSONALES
A7113: A00106 | B7113: AUTONOMO
A7114: A00107 | B7114: APORTES Y LEYES SOCIALES
A7115: A00108 | B7115: INGRESOS BRUTOS RETENIDOS
... A7128: A00208 | B7128: SEGUROS
A7129: A00300 | B7129: FLETES PROVEEDORES PINTURAS Y ACCESORIOS | C7129: 506
A7130: A00301 | B7130: FLETES PROVEEDORES OTROS SERVICIOS | C7130: 506
A7131: A00303 | B7131: FLETES INTERNOS | C7131: 506
A7132: A00304 | B7132: FLETES A CLIENTES | C7132: 506
A7133: A00305 | B7133: ALQUILERES | C7133: 728
A7134: A00306 | B7134: COMBUSTIBLES
A7135: A00307 | B7135: VARIOS LIBRERIA
A7136: A00308 | B7136: SERVICIO MECANICO | C7136: 504
A7137: A00309 | B7137: GASTOS VARIOS DE MANTENIMIENTO
A7138: A00310 | B7138: COMISIONES Y RENOVACIONES CONTRATOS
A7139: A00311 | B7139: VIATICOS
A7140: A00312 | B7140: MARKETING
A7141: A00313 | B7141: HONORARIOS PROFESIONALES
A7142: A00314 | B7142: VARIOS ELECTRICIDAD | C7142: 708
...

Sheet 001
A1: Cod. Tabla | B1: Cod.Producto | C1: Descripcion | D1: Grupo | E1: Precio Venta | F1: TES | G1: % | H1: Final | I1: Moneda
A2: 001 | B2: 000002 | C2: =IFERROR(VLOOKUP(B2,'SB1'!$A$2:$B$999999,2,FALSE),"") -> CINTA PELIGRO X 100 MTS DOBLE FAZ(CP100) | D2: 0165 | E2: =IFERROR(VLOOKUP(B2,'DA1'!$B$2:$D$999999,3,FALSE),"") | F2: =IFERROR(VLOOKUP(B2,'SB1'!$A$2:$C$999999,3,FALSE),"") -> 503 | G2: =E2*1.04 -> #VALUE! | H2: =G2*1.21 -> #VALUE! | I2: 1
A3: 001 | B3: 000003 | C3: =IFERROR(VLOOKUP(B3,'SB1'!$A$2:$B$999999,2,FALSE),"") -> CINTA PELIGRO X 200 MTS DOBLE FAZ(CP200) | D3: 0165 | E3: =IFERROR(VLOOKUP(B3,'DA1'!$B$2:$D$999999,3,FALSE),"") | F3: =IFERROR(VLOOKUP(B3,'SB1'!$A$2:$C$999999,3,FALSE),"") -> 503 | G3: =E3*1.04 -> #VALUE! | H3: =G3*1.21 -> #VALUE! | I3: 1
A4: 001 | B4: 000004 | C4: =IFERROR(VLOOKUP(B4,'SB1'!$A$2:$B$999999,2,FALSE),"") -> PISTOLA APLICADORA SKELETOR REFORZADA | D4: 0165 | E4: =IFERROR(VLOOKUP(B4,'DA1'!$B$2:$D$999999,3,FALSE),"") | F4: =IFERROR(VLOOKUP(B4,'SB1'!$A$2:$C$999999,3,FALSE),"") -> 503 | G4: =E4*1.04 -> #VALUE! | H4: =G4*1.21 -> #VALUE! | I4: 1
A5: 001 | B5: 000005 | C5: =IFERROR(VLOOKUP(B5,'SB1'!$A$2:$B$999999,2,FALSE),"") -> PORTA PINCEL MAGNETICO | D5: 0165 | E5: =IFERROR(VLOOKUP(B5,'DA1'!$B$2:$D$999999,3,FALSE),"") | F5: =IFERROR(VLOOKUP(B5,'SB1'!$A$2:$C$999999,3,FALSE),"") -> 503 | G5: =E5*1.04 -> #VALUE! | H5: =G5*1.21 -> #VALUE! | I5: 1
A6: 001 | B6: 000006 | C6: =IFERROR(VLOOKUP(B6,'SB1'!$A$2:$B$999999,2,FALSE),"") -> COBERTURA PLASTICA MULTIUSO 3X3MTS.(AC315) | D6: 0165 | E6: =IFERROR(VLOOKUP(B6,'DA1'!$B$2:$D$999999,3,FALSE),"") | F6: =IFERROR(VLOOKUP(B6,'SB1'!$A$2:$C$999999,3,FALSE),"") -> 503 | G6: =E6*1.04 -> #VALUE! | H6: =G6*1.21 -> #VALUE! | I6: 1
A7: 001 | B7: 000007 | C7: =IFERROR(VLOOKUP(B7,'SB1'!$A$2:$B$999999,2,FALSE),"") -> COBERTURA PLASTICA MULTIUSO 3X4MTS.(AC316) | D7: 0165 | E7: =IFERROR(VLOOKUP(B7,'DA1'!$B$2:$D$999999,3,FALSE),"") | F7: =IFERROR(VLOOKUP(B7,'SB1'!$A$2:$C$999999,3,FALSE),"") -> 503 | G7: =E7*1.04 -> #VALUE! | H7: =G7*1.21 -> #VALUE! | I7: 1
A8: 001 | B8: 000008 | C8: =IFERROR(VLOOKUP(B8,'SB1'!$A$2:$B$999999,2,FALSE),"") -> COBERTURA PLASTICA MULTIUSO 3X5MTS.(AC317) | D8: 0165 | E8: =IFERROR(VLOOKUP(B8,'DA1'!$B$2:$D$999999,3,FALSE),"") | F8: =IFERROR(VLOOKUP(B8,'SB1'!$A$2:$C$999999,3,FALSE),"") -> 503 | G8: =E8*1.04 -> #VALUE! | H8: =G8*1.21 -> #VALUE! | I8: 1
A9: 001 | B9: 000010 | C9: =IFERROR(VLOOKUP(B9,'SB1'!$A$2:$B$999999,2,FALSE),"") -> ESMALTE SINTETICO TERSUAVE 2EN1 MATE NEGRO X 0,500 | D9: 0152 | E9: =IFERROR(VLOOKUP(B9,'DA1'!$B$2:$D$999999,3,FALSE),"") | F9: =IFERROR(VLOOKUP(B9,'SB1'!$A$2:$C$999999,3,FALSE),"") -> 503 | G9: =E9*1.04 -> #VALUE! | H9: =G9*1.21 -> #VALUE! | I9: 1
A10: 001 | B10: 000011 | C10: =IFERROR(VLOOKUP(B10,'SB1'!$A$2:$B$999999,2,FALSE),"") -> ESMALTE SINTETICO TERSUAVE 2EN1 MATE NEGRO X 1 | D10: 0152 | E10: =IFERROR(VLOOKUP(B10,'DA1'!$B$2:$D$999999,3,FALSE),"") | F10: =IFERROR(VLOOKUP(B10,'SB1'!$A$2:$C$999999,3,FALSE),"") -> 503 | G10: =E10*1.04 -> #VALUE! | H10: =G10*1.21 -> #VALUE! | I10: 1
A11: 001 | B11: 000012 | C11: =IFERROR(VLOOKUP(B11,'SB1'!$A$2:$B$999999,2,FALSE),"") -> ESMALTE SINTETICO TERSUAVE 2EN1 MATE NEGRO X 4 | D11: 0152 | E11: =IFERROR(VLOOKUP(B11,'DA1'!$B$2:$D$999999,3,FALSE),"") | F11: =IFERROR(VLOOKUP(B11,'SB1'!$A$2:$C$999999,3,FALSE),"") -> 503 | G11: =E11*1.04 -> #VALUE! | H11: =G11*1.21 -> #VALUE! | I11: 1
A12: 001 | B12: 000013 | C12: =IFERROR(VLOOKUP(B12,'SB1'!$A$2:$B$999999,2,FALSE),"") -> ESMALTE SINTETICO TERSUAVE 2EN1 MATE BLANCO X 0,500 | D12: 0152 | E12: =IFERROR(VLOOKUP(B12,'DA1'!$B$2:$D$999999,3,FALSE),"") | F12: =IFERROR(VLOOKUP(B12,'SB1'!$A$2:$C$999999,3,FALSE),"") -> 503 | G12: =E12*1.04 -> #VALUE! | H12: =G12*1.21 -> #VALUE! | I12: 1
A13: 001 | B13: 000014 | C13: =IFERROR(VLOOKUP(B13,'SB1'!$A$2:$B$999999,2,FALSE),"") -> ESMALTE SINTETICO TERSUAVE 2EN1 MATE BLANCO X 1 | D13: 0152 | E13: =IFERROR(VLOOKUP(B13,'DA1'!$B$2:$D$999999,3,FALSE),"") | F13: =IFERROR(VLOOKUP(B13,'SB1'!$A$2:$C$999999,3,FALSE),"") -> 503 | G13: =E13*1.04 -> #VALUE! | H13: =G13*1.21 -> #VALUE! | I13: 1
... A16: 001 | B16: 000025 | C16: =IFERROR(VLOOKUP(B16,'SB1'!$A$2:$B$999999,2,FALSE),"") -> AUTOPOLISH COLORIN BICAPA X 0,450 | D16: 0166 | E16: =IFERROR(VLOOKUP(B16,'DA1'!$B$2:$D$999999,3,FALSE),"") | F16: =IFERROR(VLOOKUP(B16,'SB1'!$A$2:$C$999999,3,FALSE),"") -> 503 | G16: =E16*1.04 -> #VALUE! | H16: =G16*1.21 -> #VALUE! | I16: 1
A17: 001 | B17: 000026 | C17: =IFERROR(VLOOKUP(B17,'SB1'!$A$2:$B$999999,2,FALSE),"") -> BARNIZ PARA MADERA EXTERIOR ALBATROS AL AGUA BRILLANTE INCOLORO X 1 | D17: 0902 | E17: =IFERROR(VLOOKUP(B17,'DA1'!$B$2:$D$999999,3,FALSE),"") | F17: =IFERROR(VLOOKUP(B17,'SB1'!$A$2:$C$999999,3,FALSE),"") -> 503 | G17: =E17*1.04 -> #VALUE! | H17: =G17*1.21 -> #VALUE!
A18: 001 | B18: 000027 | C18: =IFERROR(VLOOKUP(B18,'SB1'!$A$2:$B$999999,2,FALSE),"") -> BARNIZ PARA MADERA EXTERIOR ALBATROS AL AGUA BRILLANTE INCOLORO X 4 | D18: 0902 | E18: =IFERROR(VLOOKUP(B18,'DA1'!$B$2:$D$999999,3,FALSE),"") | F18: =IFERROR(VLOOKUP(B18,'SB1'!$A$2:$C$999999,3,FALSE),"") -> 503 | G18: =E18*1.04 -> #VALUE! | H18: =G18*1.21 -> #VALUE! | I18: 1
A19: 001 | B19: 000028 | C19: =IFERROR(VLOOKUP(B19,'SB1'!$A$2:$B$999999,2,FALSE),"") -> REMOVEDOR GEL PETRILAC X 4 | D19: 0902 | E19: =IFERROR(VLOOKUP(B19,'DA1'!$B$2:$D$999999,3,FALSE),"") | F19: =IFERROR(VLOOKUP(B19,'SB1'!$A$2:$C$999999,3,FALSE),"") -> 503 | G19: =E19*1.04 -> #VALUE! | H19: =G19*1.21 -> #VALUE!
A20: 001 | B20: 000034 | C20: =IFERROR(VLOOKUP(B20,'SB1'!$A$2:$B$999999,2,FALSE),"") -> LATEX PARA CIELORRASOS COLORIN MATE BLANCO X 20 | D20: 0116 | E20: =IFERROR(VLOOKUP(B20,'DA1'!$B$2:$D$999999,3,FALSE),"") | F20: =IFERROR(VLOOKUP(B20,'SB1'!$A$2:$C$999999,3,FALSE),"") -> 503 | G20: =E20*1.04 -> #VALUE! | H20: =G20*1.21 -> #VALUE! | I20: 1
A21: 001 | B21: 000041 | C21: =IFERROR(VLOOKUP(B21,'SB1'!$A$2:$B$999999,2,FALSE),"") -> BARNIZ PARA MADERA INTERIOR CRISTALBA PU MATE NATURAL X 1 | D21: 0107 | E21: =IFERROR(VLOOKUP(B21,'DA1'!$B$2:$D$999999,3,FALSE),"") | F21: =IFERROR(VLOOKUP(B21,'SB1'!$A$2:$C$999999,3,FALSE),"") -> 503 | G21: =E21*1.04 -> #VALUE! | H21: =G21*1.21 -> #VALUE! | I21: 1
A22: 001 | B22: 000042 | C22: =IFERROR(VLOOKUP(B22,'SB1'!$A$2:$B$999999,2,FALSE),"") -> BARNIZ PARA MADERA INTERIOR CRISTALBA PU MATE NATURAL X 4 | D22: 0107 | E22: =IFERROR(VLOOKUP(B22,'DA1'!$B$2:$D$999999,3,FALSE),"") | F22: =IFERROR(VLOOKUP(B22,'SB1'!$A$2:$C$999999,3,FALSE),"") -> 503 | G22: =E22*1.04 -> #VALUE! | H22: =G22*1.21 -> #VALUE! | I22: 1
A23: 001 | B23: 000043 | C23: =IFERROR(VLOOKUP(B23,'SB1'!$A$2:$B$999999,2,FALSE),"") -> MEZCLADOR PROFESIONAL(MIXER) Ø8CMX40CM | D23: 0165 | E23: =IFERROR(VLOOKUP(B23,'DA1'!$B$2:$D$999999,3,FALSE),"") | F23: =IFERROR(VLOOKUP(B23,'SB1'!$A$2:$C$999999,3,FALSE),"") -> 503 | G23: =E23*1.04 -> #VALUE! | H23: =G23*1.21 -> #VALUE! | I23: 1
A24: 001 | B24: 000044 | C24: =IFERROR(VLOOKUP(B24,'SB1'!$A$2:$B$999999,2,FALSE),"") -> PALETA ABRELATA 30CM | D24: 0165 | E24: =IFERROR(VLOOKUP(B24,'DA1'!$B$2:$D$999999,3,FALSE),"") | F24: =IFERROR(VLOOKUP(B24,'SB1'!$A$2:$C$999999,3,FALSE),"") -> 503 | G24: =E24*1.04 -> #VALUE! | H24: =G24*1.21 -> #VALUE! | I24: 1
A25: 001 | B25: 000046 | C25: =IFERROR(VLOOKUP(B25,'SB1'!$A$2:$B$999999,2,FALSE),"") -> JUEGO DE LAMINAS DE MASILLAR (5-8-10-12) | D25: 0165 | E25: =IFERROR(VLOOKUP(B25,'DA1'!$B$2:$D$999999,3,FALSE),"") | F25: =IFERROR(VLOOKUP(B25,'SB1'!$A$2:$C$999999,3,FALSE),"") -> 503 | G25: =E25*1.04 -> #VALUE! | H25: =G25*1.21 -> #VALUE! | I25: 1
A26: 001 | B26: 000050 | C26: =IFERROR(VLOOKUP(B26,'SB1'!$A$2:$B$999999,2,FALSE),"") -> TRINCHETA-CUTTER PRO GUIA METAL USO PESADO | D26: 0165 | E26: =IFERROR(VLOOKUP(B26,'DA1'!$B$2:$D$999999,3,FALSE),"") | F26: =IFERROR(VLOOKUP(B26,'SB1'!$A$2:$C$999999,3,FALSE),"") -> 503 | G26: =E26*1.04 -> #VALUE! | H26: =G26*1.21 -> #VALUE! | I26: 1
A27: 001 | B27: 000051 | C27: =IFERROR(VLOOKUP(B27,'SB1'!$A$2:$B$999999,2,FALSE),"") -> GUANTE NITRILO SOFT NEGRO S/P #XL MEDIGLOVE X 100 | D27: 0177 | E27: =IFERROR(VLOOKUP(B27,'DA1'!$B$2:$D$999999,3,FALSE),"") | F27: =IFERROR(VLOOKUP(B27,'SB1'!$A$2:$C$999999,3,FALSE),"") -> 503 | G27: =E27*1.04 -> #VALUE! | H27: =G27*1.21 -> #VALUE! | I27: 1
A28: 001 | B28: 000052 | C28: =IFERROR(VLOOKUP(B28,'SB1'!$A$2:$B$999999,2,FALSE),"") -> BALDE PLASTICO REFORZADO 8LTS. (BC01) | D28: 0176 | E28: =IFERROR(VLOOKUP(B28,'DA1'!$B$2:$D$999999,3,FALSE),"") | F28: =IFERROR(VLOOKUP(B28,'SB1'!$A$2:$C$999999,3,FALSE),"") -> 503 | G28: =E28*1.04 -> #VALUE! | H28: =G28*1.21 -> #VALUE! | I28: 1
A29: 001 | B29: 000054 | C29: =IFERROR(VLOOKUP(B29,'SB1'!$A$2:$B$999999,2,FALSE),"") -> BASE ACRILICA-UNIVERSAL MMB X 0,875 | D29: 0137 | E29: =IFERROR(VLOOKUP(B29,'DA1'!$B$2:$D$999999,3,FALSE),"") | F29: =IFERROR(VLOOKUP(B29,'SB1'!$A$2:$C$999999,3,FALSE),"") -> 503 | G29: =E29*1.04 -> #VALUE! | H29: =G29*1.21 -> #VALUE! | I29: 1
A30: 001 | B30: 000055 | C30: =IFERROR(VLOOKUP(B30,'SB1'!$A$2:$B$999999,2,FALSE),"") -> BASE ACRILICA-UNIVERSAL MMB X 3,500 | D30: 0137 | E30: =IFERROR(VLOOKUP(B30,'DA1'!$B$2:$D$999999,3,FALSE),"") | F30: =IFERROR(VLOOKUP(B30,'SB1'!$A$2:$C$999999,3,FALSE),"") -> 503 | G30: =E30*1.04 -> #VALUE! | H30: =G30*1.21 -> #VALUE! | I30: 1
A31: 001 | B31: 000057 | C31: =IFERROR(VLOOKUP(B31,'SB1'!$A$2:$B$999999,2,FALSE),"") -> FONDO ANTIOXIDO UNIVERSAL MMB X 1 | D31: 0137 | E31: =IFERROR(VLOOKUP(B31,'DA1'!$B$2:$D$999999,3,FALSE),"") | F31: =IFERROR(VLOOKUP(B31,'SB1'!$A$2:$C$999999,3,FALSE),"") -> 503 | G31: =E31*1.04 -> #VALUE! | H31: =G31*1.21 -> #VALUE! | I31: 1
... A33: 001 | B33: 000059 | C33: =IFERROR(VLOOKUP(B33,'SB1'!$A$2:$B$999999,2,FALSE),"") -> MASILLA UNIVERSAL MMB X 1 | D33: 0137 | E33: =IFERROR(VLOOKUP(B33,'DA1'!$B$2:$D$999999,3,FALSE),"") | F33: =IFERROR(VLOOKUP(B33,'SB1'!$A$2:$C$999999,3,FALSE),"") -> 503 | G33: =E33*1.04 -> #VALUE! | H33: =G33*1.21 -> #VALUE! | I33: 1
A34: 001 | B34: 000060 | C34: =IFERROR(VLOOKUP(B34,'SB1'!$A$2:$B$999999,2,FALSE),"") -> MASILLA UNIVERSAL MMB X 4 | D34: 0902 | E34: =IFERROR(VLOOKUP(B34,'DA1'!$B$2:$D$999999,3,FALSE),"") | F34: =IFERROR(VLOOKUP(B34,'SB1'!$A$2:$C$999999,3,FALSE),"") -> 503 | G34: =E34*1.04 -> #VALUE! | H34: =G34*1.21 -> #VALUE!
A35: 001 | B35: 000065 | C35: =IFERROR(VLOOKUP(B35,'SB1'!$A$2:$B$999999,2,FALSE),"") -> LATEX EXTERIOR COLORIN TITANIO PRO BLANCO X 10 | D35: 0116 | E35: =IFERROR(VLOOKUP(B35,'DA1'!$B$2:$D$999999,3,FALSE),"") | F35: =IFERROR(VLOOKUP(B35,'SB1'!$A$2:$C$999999,3,FALSE),"") -> 503 | G35: =E35*1.04 -> #VALUE! | H35: =G35*1.21 -> #VALUE! | I35: 1
A36: 001 | B36: 000067 | C36: =IFERROR(VLOOKUP(B36,'SB1'!$A$2:$B$999999,2,FALSE),"") -> PROTECTOR PARA MADERA CETOL BELLEZA NATURAL MATE INCOLORO X 1 | D36: 0105 | E36: =IFERROR(VLOOKUP(B36,'DA1'!$B$2:$D$999999,3,FALSE),"") | F36: =IFERROR(VLOOKUP(B36,'SB1'!$A$2:$C$999999,3,FALSE),"") -> 503 | G36: =E36*1.04 -> #VALUE! | H36: =G36*1.21 -> #VALUE! | I36: 1
A37: 001 | B37: 000068 | C37: =IFERROR(VLOOKUP(B37,'SB1'!$A$2:$B$999999,2,FALSE),"") -> PROTECTOR PARA MADERA CETOL BELLEZA NATURAL MATE INCOLORO X 4 | D37: 0105 | E37: =IFERROR(VLOOKUP(B37,'DA1'!$B$2:$D$999999,3,FALSE),"") | F37: =IFERROR(VLOOKUP(B37,'SB1'!$A$2:$C$999999,3,FALSE),"") -> 503 | G37: =E37*1.04 -> #VALUE! | H37: =G37*1.21 -> #VALUE! | I37: 1
A38: 001 | B38: 000071 | C38: =IFERROR(VLOOKUP(B38,'SB1'!$A$2:$B$999999,2,FALSE),"") -> CUCHARA WELBY N 7 (CU02) | D38: 0176 | E38: =IFERROR(VLOOKUP(B38,'DA1'!$B$2:$D$999999,3,FALSE),"") | F38: =IFERROR(VLOOKUP(B38,'SB1'!$A$2:$C$999999,3,FALSE),"") -> 503 | G38: =E38*1.04 -> #VALUE! | H38: =G38*1.21 -> #VALUE! | I38: 1
A39: 001 | B39: 000072 | C39: =IFERROR(VLOOKUP(B39,'SB1'!$A$2:$B$999999,2,FALSE),"") -> ESMALTE SINTETICO TERSUAVE 2EN1 MATE NEGRO X 20 | D39: 0152 | E39: =IFERROR(VLOOKUP(B39,'DA1'!$B$2:$D$999999,3,FALSE),"") | F39: =IFERROR(VLOOKUP(B39,'SB1'!$A$2:$C$999999,3,FALSE),"") -> 503 | G39: =E39*1.04 -> #VALUE! | H39: =G39*1.21 -> #VALUE! | I39: 1
A40: 001 | B40: 000073 | C40: =IFERROR(VLOOKUP(B40,'SB1'!$A$2:$B$999999,2,FALSE),"") -> D8501 PRIMER 2K DP4000 BLANCO AUTONIVELANTE (G1) X 1 | D40: 0134 | E40: =IFERROR(VLOOKUP(B40,'DA1'!$B$2:$D$999999,3,FALSE),"") | F40: =IFERROR(VLOOKUP(B40,'SB1'!$A$2:$C$999999,3,FALSE),"") -> 503 | G40: =E40*1.04 -> #VALUE! | H40: =G40*1.21 -> #VALUE! | I40: 3
A41: 001 | B41: 000074 | C41: =IFERROR(VLOOKUP(B41,'SB1'!$A$2:$B$999999,2,FALSE),"") -> D8507 PRIMER 2K DP4000 GRIS AUTONIVELANTE (G7) X 1 | D41: 0134 | E41: =IFERROR(VLOOKUP(B41,'DA1'!$B$2:$D$999999,3,FALSE),"") | F41: =IFERROR(VLOOKUP(B41,'SB1'!$A$2:$C$999999,3,FALSE),"") -> 503 | G41: =E41*1.04 -> #VALUE! | H41: =G41*1.21 -> #VALUE! | I41: 3
A42: 001 | B42: 000075 | C42: =IFERROR(VLOOKUP(B42,'SB1'!$A$2:$B$999999,2,FALSE),"") -> D8238 CATALIZADOR P/ D8115 / D8117 / D8501/D8507 (DP4000) X 0,500 "DISCONTINUADO" | D42: 0902 | E42: =IFERROR(VLOOKUP(B42,'DA1'!$B$2:$D$999999,3,FALSE),"") | F42: =IFERROR(VLOOKUP(B42,'SB1'!$A$2:$C$999999,3,FALSE),"") -> 503 | G42: =E42*1.04 -> #VALUE! | H42: =G42*1.21 -> #VALUE!
A43: 001 | B43: 000078 | C43: =IFERROR(VLOOKUP(B43,'SB1'!$A$2:$B$999999,2,FALSE),"") -> LATEX PARA CIELORRASOS COLORIN MATE BLANCO X 10 | D43: 0116 | E43: =IFERROR(VLOOKUP(B43,'DA1'!$B$2:$D$999999,3,FALSE),"") | F43: =IFERROR(VLOOKUP(B43,'SB1'!$A$2:$C$999999,3,FALSE),"") -> 503 | G43: =E43*1.04 -> #VALUE! | H43: =G43*1.21 -> #VALUE! | I43: 1
...

Sheet DA1
A1: Cod. Tabla | B1: Cod.Producto | C1: Grupo | D1: Precio Venta | E1: Moneda
A2: 1 | B2: 2 | C2: 165 | D2: 7361.28 | E2: 1
A3: 1 | B3: 3 | C3: 165 | D3: 8634.19 | E3: 1
A4: 1 | B4: 4 | C4: 165 | D4: 5167.87 | E4: 1
A5: 1 | B5: 5 | C5: 902 | D5: 1150.05 | E5: 1
A6: 1 | B6: 6 | C6: 165 | D6: 5150.97 | E6: 1
A7: 1 | B7: 7 | C7: 165 | D7: 6906.78 | E7: 1
A8: 1 | B8: 8 | C8: 165 | D8: 8930.2 | E8: 1
A9: 1 | B9: 10 | C9: 152 | D9: 10082.07 | E9: 1
A10: 1 | B10: 11 | C10: 152 | D10: 15006.36 | E10: 1
A11: 1 | B11: 12 | C11: 152 | D11: 52809.36 | E11: 1
A12: 1 | B12: 13 | C12: 152 | D12: 11883.21 | E12: 1
A13: 1 | B13: 14 | C13: 152 | D13: 18043.58 | E13: 1
... A4629: 1 | B4629: 200623 | C4629: 120 | D4629: 219056.08 | E4629: 1

Sheet ListaCorte
A1: Cod.Producto | B1: Descripcion | C1: Grupo | D1: Final | E1: Moneda
A2: ='001'!B2 -> 000002 | B2: ='001'!C2 -> CINTA PELIGRO X 100 MTS DOBLE FAZ(CP100) | C2: ='001'!D2 -> 0165 | D2: ='001'!H2 -> #VALUE!
A3: ='001'!B3 -> 000003 | B3: ='001'!C3 -> CINTA PELIGRO X 200 MTS DOBLE FAZ(CP200) | C3: ='001'!D3 -> 0165 | D3: ='001'!H3 -> #VALUE!
A4: ='001'!B4 -> 000004 | B4: ='001'!C4 -> PISTOLA APLICADORA SKELETOR REFORZADA | C4: ='001'!D4 -> 0165 | D4: ='001'!H4 -> #VALUE!
A5: ='001'!B5 -> 000005 | B5: ='001'!C5 -> PORTA PINCEL MAGNETICO | C5: ='001'!D5 -> 0165 | D5: ='001'!H5 -> #VALUE!
A6: ='001'!B6 -> 000006 | B6: ='001'!C6 -> COBERTURA PLASTICA MULTIUSO 3X3MTS.(AC315) | C6: ='001'!D6 -> 0165 | D6: ='001'!H6 -> #VALUE!
A7: ='001'!B7 -> 000007 | B7: ='001'!C7 -> COBERTURA PLASTICA MULTIUSO 3X4MTS.(AC316) | C7: ='001'!D7 -> 0165 | D7: ='001'!H7 -> #VALUE!
A8: ='001'!B8 -> 000008 | B8: ='001'!C8 -> COBERTURA PLASTICA MULTIUSO 3X5MTS.(AC317) | C8: ='001'!D8 -> 0165 | D8: ='001'!H8 -> #VALUE!
A9: ='001'!B9 -> 000010 | B9: ='001'!C9 -> ESMALTE SINTETICO TERSUAVE 2EN1 MATE NEGRO X 0,500 | C9: ='001'!D9 -> 0152 | D9: ='001'!H9 -> #VALUE!
A10: ='001'!B10 -> 000011 | B10: ='001'!C10 -> ESMALTE SINTETICO TERSUAVE 2EN1 MATE NEGRO X 1 | C10: ='001'!D10 -> 0152 | D10: ='001'!H10 -> #VALUE!
A11: ='001'!B11 -> 000012 | B11: ='001'!C11 -> ESMALTE SINTETICO TERSUAVE 2EN1 MATE NEGRO X 4 | C11: ='001'!D11 -> 0152 | D11: ='001'!H11 -> #VALUE!
A12: ='001'!B12 -> 000013 | B12: ='001'!C12 -> ESMALTE SINTETICO TERSUAVE 2EN1 MATE BLANCO X 0,500 | C12: ='001'!D12 -> 0152 | D12: ='001'!H12 -> #VALUE!
A13: ='001'!B13 -> 000014 | B13: ='001'!C13 -> ESMALTE SINTETICO TERSUAVE 2EN1 MATE BLANCO X 1 | C13: ='001'!D13 -> 0152 | D13: ='001'!H13 -> #VALUE!
... A4628: ='001'!B4628 -> 200623 | B4628: ='001'!C4628 -> DILUYENTE SECADO A AIRE DIXILINA NRO.3 X 200 | C4628: ='001'!D4628 -> 0120 | D4628: ='001'!H4628 -> #VALUE!
